Workbook

Sheet 4173  General
A1: MONTHLY STATUS REPORT No.: | C1: 4 | E1: Date : | F1: 43048
A2: [1] MR shall be referred for furnishing all the below information during fist report. Later as per PR. [2] The below information is required to be submitted to EIL, RPO: Chennai within 1 Week from the date of Receipt of FOA, for all new Orders under EIL's Inspection. | E2: Expected Order Completion Date by Vendor | F2: Vendor's Internal Work Order Ref.
E3: 43183 | F3: J 4173
A4: Client: | B4: M/s.IOCL GUJARAT | C4: Project: | D4: BS VI, UNIT - HGU | G4: Contractual Delivery Date
A5: Vendor: | B5: TITANIUM EQUIPMENT AND ANODE MFG CO LTD | D5: Location: | E5: CHENNAI | G5: 43197
A6: FOA No.:
A7: FOA Date: | C7: Date of Receipt of FOA by Vendor:
A8: Item | B8: HEAT EXCHANGER - SS | F8: Qty : | G8: 5 NOS
A9: FOA Accepted vide Vendor's Letter No. | F9: Date
A10: PO No. | B10: A885/6136/520/PO-173 | F10: Date: | G10: 09.05.2017
A11: PR No. / Rev. No. | B11: A885-602-EE-PR-6136-0173 | F11: Date: | G11: 02.06.2017
A13: Submission Date(s) of: | D13: Constraints:
A14: [1] "List of Drawings Approval" | B14: Refer the below drawing status | D14: [1] Financial Problems: | F14: NIL
A15: [2] "List of Items to be sub-ordered" | D15: [2] Labour Unrest: | F15: NIL
A16: [3] QAP | B16: Not Submitted | D16: [3] Overloading: | F16: NIL
A17: [4] Manufacturing Schedule | D17: [4] Any Other: | F17: NIL
A19: QAP No. : | D19: Manfacturing Schedule (MS) [Update Monthly]
A20: QAP Rev. No.: | B20: 0
A21: QAP Approved by EIL on:
A23: Raw Material: | B23: Inhouse \ Yet to be sub-ordered \ Sub-ordered and received / not received
A24: Item | B24: Availability Location In-house / Sub-ordered | D24: Item | F24: Availability Location In-house / Sub-ordered
A25: Tubes - SA213TP321, SA213TP304 | B25: MUMBAI
A26: Forgings- STD- SA182F321, SA182F304 NON STD- SA965F321, SA965F304 | B26: NEW DELHI
A27: Fasteners | B27: Yet to be sub-ordered
A28: SS plates-SA240GR321, SA240GR304 | B28: MUMBAI
A29: CS plates-SA516GR60, SA516GR70 | B29: Yet to be sub-ordered
A30: Gasket | B30: Yet to be sub-ordered
A35: Note(s): | B35: 1. All the Major / Critical Components shall be listed in the Table.
B36: 2. If the Drawings will be submitted later, indicate the anticipated submission date in Remarks.
A38: Drawings: | C38: * - Anticipated / Actual
A39: Title & Drawing No. | B39: Rev. No. | C39: *Submission Date to EIL Review | D39: Date of Receipt of Drawings from EIL | E39: EIL Review Code | F39: Date of re-submission of Drawings for EIL Review | G39: Any Input specifically required from EIL.
A40: GENERAL ASSEMBLY DETAILS - TEAM-HX-4173A-GA-001 | B40: 1 | C40: 42998 | D40: 43021 | E40: R
A41: TUBE SHEET, TUBE BUNDLE, BAFFLE AND COMPONENT DETAILS - TEAM-HX-4173A-FD-001 | B41: 1 | C41: 42998 | D41: 43021 | E41: R
A42: NOZZLES, SADDLE AND BILL OF MATERIALS - TEAM-HX-4173A-FD-002 | B42: 1 | C42: 42998 | D42: 43021 | E42: R
A43: GASKET DETAILS- TEAM-HX-4173A-FD-003 | B43: 0 | C43: 42937 | D43: 42958 | E43: R
A44: NAME PLATE DETAILS - TEAM-HX-4173A-FD-004 | B44: 0 | C44: 42937 | D44: 42958 | E44: R
A45: MANDATORY SPARE DETAILS - TEAM-HX-4173A-FD-005 | B45: 0 | C45: 42937 | D45: 42958 | E45: R
A46: GENERAL ASSEMBLY DETAILS- TEAM-HX-4173B-GA-001 | B46: 1 | C46: 42998 | D46: 43021 | E46: R
A47: TUBE SHEET, TUBE BUNDLE, BAFFLE AND COMPONENT DETAILS- TEAM-HX-4173B-FD-001 | B47: 0 | C47: 42935 | D47: 42958 | E47: R
A48: NOZZLES, SADDLE AND BILL OF MATERIALS- TEAM-HX-4173B-FD-002 | B48: 0 | C48: 42935 | D48: 42958 | E48: R
...

Sheet 4077-A609 097-II
A1: Vendor:M/s | C1: ='4173 General'!B5 -> TITANIUM EQUIPMENT AND ANODE MFG CO LTD | I1: FOA No. : | J1: ='4173 General'!B6 -> 0 | U1: Status Report Date: | W1: ='4173 General'!F1 -> 43048
A2: Item: | C2: ='4173 General'!B8 -> HEAT EXCHANGER - SS | I2: PO No. : | J2: ='4173 General'!B10 -> A885/6136/520/PO-173 | T2: ='4173 General'!F2 -> Vendor's Internal Work Order Ref. | W2: ='4173 General'!F3 -> J 4173
A4: FOA Sl# | B4: PR Sl.# | C4: PO Sl.# | D4: Your Line Item No. | E4: Type / Model / Part No. | F4: Tag Number | G4: Size | H4: Rating | I4: H2 Ser vice | J4: IBR | K4: NACE | L4: RT % | M4: Qty As per P.O. in Nos. | N4: Qty Completed in Nos. | O4: Qty Balance in Nos. | P4: Line Item# Partial/ Complete | Q4: Raw Material Available Qty in Nos. * | R4: Balance Raw Material expected by (Date) * | S4: Qty of Items Under Assembly | T4: Items Exptd by for EIL or TPI or IBR Inspn by dd/mm/yy | U4: Despatch Details- LR No. | V4: Despatch Details- LR Date | W4: Despatch Details- Transporter Name
A5: A609/097 | B5: A609-103-EE-PR-6038-0097 | D5: J4077 | N5: 0 | O5: =M5-N5 -> 0
O6: =M6-N6 -> 0
O7: =M7-N7 -> 0
O10: =M10-N10 -> 0
A12: Add additional rows, above, if required, as per EIL PR Line Items. | J12: Total = | M12: =SUM(M5:M10) -> 0 | N12: =SUM(N5:N10) -> 0 | O12: =SUM(O5:O10) -> 0 | Q12: =SUM(Q5:Q10) -> 0 | S12: =SUM(S5:S10) -> 0
A13: * - In case of Imported Components / Fully Assembled Components are ordered, please mention "Import: __".
A15: Fill in either one of "Bulk Item type" or "Fabricated Item type":
A16: For BULK Items: | Q16: For FABRICATION Items:
A17: Milestones: | F17: Original Scheduled Date | H17: Present Schedule Date | L17: Actual Date | O17: Qty. | Q17: Milestones: | T17: Original Scheduled Date | U17: Present Schedule Date | V17: Actual Date | W17: Qty.
A18: 1 | B18: Drawing Submission | F18: 42605 | H18: 42605 | L18: 30-Aug -16 | Q18: 1 | R18: Submission of GA Drawings forApproval | T18: 23-AUG-16 | U18: 01-SEP-16 | V18: 01-SEP-16
A19: =A18+1 -> 2 | B19: Drawing Approval | F19: =F18+30 -> 42635 | H19: =H18+30 -> 42635 | L19: 30-Aug -17 | Q19: =Q18+1 -> 2 | R19: Receipt of Approval of Drawings | T19: 08-SEP16 | U19: 19-SEP16 | V19: 19-SEP-16
A20: =A19+1 -> 3 | B20: Subordering of Material | F20: 42658 | H20: 42658 | L20: 15-OCT-16 | Q20: =Q19+1 -> 3 | R20: Release of sub orders | T20: 15-OCT-16 | U20: 15-OCT-16 | V20: 15-OCT-16
A21: =A20+1 -> 4 | B21: Receipt of Material | F21: 42735 | H21: 42735 | Q21: =Q20+1 -> 4 | R21: Receipt of sub orders | T21: 31-12-16 | U21: 30-1-17
A22: =A21+1 -> 5 | B22: Manufacturing | F22: 42824 | H22: 42824 | Q22: =Q21+1 -> 5 | R22: Long seam welding completion | T22: 42720 | U22: 42765
A23: =A22+1 -> 6 | B23: Testing and Inspection | F23: 42840 | H23: 42840 | Q23: =Q22+1 -> 6 | R23: Circ seam welding completion | T23: 31-12-16 | U23: 30-1-17
A24: =A23+1 -> 7 | B24: Despatch | F24: 42855 | H24: 42855 | Q24: =Q23+1 -> 7 | R24: Fabrication completion | T24: 25-3-17 | U24: 10-4-17
Q25: =Q24+1 -> 8 | R25: Hydrotest | T25: 7-4-17 | U25: 15-4-17
Q26: =Q25+1 -> 9 | R26: Despatch | T26: 15-4-17 | U26: 22-4-17

Sheet 4173 Mfg
A1: Vendor:M/s | C1: ='[1]4077-A609 097-I'!B5 -> TITANIUM EQUIPMENT AND ANODE MFG CO LTD | I1: FOA No. : | U1: Status Report Date: | W1: 43048
A2: Item: | C2: ='[1]4077-A609 097-I'!B8 -> HEAT EXCHANGER | I2: PO No. : | J2: A885/6136/520/PO-173 | T2: ='[1]4077-A609 097-I'!F2 -> Vendor'sInternalWork Order Ref. | W2: J4173
A4: FOA Sl# | B4: PR Sl.# | C4: PO Sl.# | D4: Your Line Item No. | E4: Type / Model / Part No. | F4: Tag Number | G4: Size | H4: Rating | I4: H2 Ser vice | J4: IBR | K4: NACE | L4: RT % | M4: Qty As per P.O. in Nos. | N4: Qty Completed in Nos. | O4: Qty Balance in Nos. | P4: Line Item# Partial/ Complete | Q4: Raw Material Available Qty in Nos. * | R4: Balance Raw Material expected by (Date) * | S4: Qty of Items Under Assembly | T4: Items Exptd by for EIL or TPI or IBR Inspn by dd/mm/yy | U4: Despatch Details- LR No. | V4: Despatch Details- LR Date | W4: Despatch Details- Transporter Name
B5: A885-602-EE-PR-6136-0173 | C5: A885/6136/520/PO-173 | D5: 1.01 | E5: FEED/EFFLUENT EXCHANGER | F5: 602-E-02 A/B | G5: 984 X 5500 | I5: N | J5: N | K5: N | L5: 100 | M5: 2 | N5: 0 | O5: 2
B6: A885-602-EE-PR-6136-0173 | C6: A885/6136/520/PO-173 | D6: 2.01 | E6: DMW PREHEATER | F6: 602-E-108 | G6: 1077 X 7590 | I6: N | J6: N | K6: N | L6: 100, 85 | M6: 1 | N6: 0 | O6: 1 | Q6: 0
B7: A885-602-EE-PR-6136-0173 | C7: A885/6136/520/PO-173 | D7: 2.02 | E7: PROCESS CONDENSATE FEED/EFFLUENT EXCHANGER | F7: 602-E-126A/B | G7: 567 X 7330 | I7: N | J7: N | K7: N | L7: 100 | M7: 2 | N7: 0 | O7: 2
N8: 0
N9: 0
N10: 0 | O10: =M10-N10 -> 0
A12: Add additional rows, above, if required, as per EIL PR Line Items. | J12: Total = | M12: =SUM(M5:M10) -> 5 | N12: =SUM(N5:N10) -> 0 | O12: =SUM(O5:O10) -> 5 | Q12: =SUM(Q5:Q10) -> 0 | S12: =SUM(S5:S10) -> 0
A13: * - In case of Imported Components / Fully Assembled Components are ordered, please mention "Import: __".
A16: Fill in either one of "Bulk Item type" or "Fabricated Item type":
A17: For BULK Items:
A18: Milestones: | F18: Original Scheduled Date | H18: Present Schedule Date | L18: Actual Date | O18: Qty.
A19: 1 | B19: Drawing Submission | F19: 42865 | L19: 42937 | O19: 5 NOS
A20: =A19+1 -> 2 | B20: Drawing Approval | F20: 42907 | L20: NOT APPROVED DRAWING IS REVISED
A21: =A20+1 -> 3 | B21: Subordering of Material | F21: 42881 | L21: Partial materials ordered and ordering started on 04.07.2017
A22: =A21+1 -> 4 | B22: Receipt of Material | F22: 43004 | L22: partial material received
A23: =A22+1 -> 5 | B23: Manufacturing | F23: 42913
A24: =A23+1 -> 6 | B24: Testing and Inspection | F24: 43174
A25: =A24+1 -> 7 | B25: Despatch | F25: 43214
A28: MANUFACTURING STATUS FOR TAG NO: 602-E-02 A/B
A29: MANUFACTURING NOT YET STARTED
A31: MANUFACTURING STATUS FOR TAG NO: 602-E-108
A32: MANUFACTURING NOT YET STARTED
A34: MANUFACTURING STATUS FOR TAG NO: 602-E-126A/B
A35: MANUFACTURING NOT YET STARTED
